Workbook

Sheet Dati
A1: Nome | B1: Cognome | C1: Età | D1: Titolo di Studio | E1: Indirizzo | F1: Professione in Azienda
A2: Umberto | B2: Micca | C2: 42 | D2: Laurea magistrale | E2: Rotonda Ivo, 1 Appartamento 35, 00023, Arsoli (RM) | F2: Impiegato amministrativo
A3: Emilio | B3: Moccia | C3: 29 | D3: Laurea triennale | E3: Vicolo Ferragni, 1 Appartamento 72, 07038, Trinita' D'Agultu E Vignola (SS) | F3: Responsabile vendite
A4: Beatrice | B4: Lerner | C4: 52 | D4: Master | E4: Via Giulia, 3, 17033, Casanova Lerrone (SV) | F4: Operaio specializzato
A5: Damiano | B5: Marazzi | C5: 56 | D5: Laurea magistrale | E5: Borgo Norbiato, 75, 35045, Ospedaletto Euganeo (PD) | F5: Analista dati
A6: Paride | B6: Pepe | C6: 45 | D6: Diploma di scuola superiore | E6: Vicolo Elmo, 89 Appartamento 68, 30131, Venezia (VE) | F6: Analista dati
A7: Baccio | B7: Gabbana | C7: 21 | D7: Laurea triennale | E7: Incrocio Sinisi, 91 Appartamento 82, 95029, Viagrande (CT) | F7: Responsabile vendite
A8: Fiorenzo | B8: Gangemi | C8: 35 | D8: Master | E8: Canale Ziani, 86 Piano 5, 35014, Fontaniva (PD) | F8: Direttore risorse umane
A9: Vincenzo | B9: Filippelli | C9: 33 | D9: Master | E9: Rotonda Renata, 6 Piano 3, 84084, Fisciano (SA) | F9: Project Manager
A10: Dante | B10: Vivaldi | C10: 51 | D10: Dottorato di ricerca | E10: Canale Adelmo, 0 Appartamento 10, 35026, Conselve (PD) | F10: Analista dati
A11: Lara | B11: Respighi | C11: 42 | D11: Laurea magistrale | E11: Incrocio Villadicani, 58, 40013, Progresso (BO) | F11: Tecnico informatico
A12: Annetta | B12: Einaudi | C12: 46 | D12: Laurea magistrale | E12: Piazza Donatella, 67, 25052, Pian Di Borno (BS) | F12: Tecnico informatico
A13: Melina | B13: Basso | C13: 54 | D13: Diploma di scuola superiore | E13: Via Calcedonio, 45 Appartamento 76, 32010, Soverzene (BL) | F13: Direttore risorse umane
... A251: Domenico | B251: Porcellato | C251: 22 | D251: Diploma di scuola superiore | E251: Strada Vidoni, 50, 12049, Trinita' (CN) | F251: Impiegato amministrativo

Sheet Dati sistemati
A1: Nome | B1: Cognome | C1: Età | E1: Titolo di Studio | G1: Professione
A2: Adelmo | B2: Anichini | C2: {=VLOOKUP(A2:B2,Dati!$A$2:$F$251,3,FALSE)} -> 24 | D2: #N/A | E2: {=VLOOKUP(A2:B2,Dati!$A$2:$F$251,4,FALSE)} -> Laurea triennale | F2: #N/A | G2: {=VLOOKUP(A2:B2,Dati!A82:F331,6,FALSE)} -> Responsabile vendite | H2: #N/A
A3: Adriana | B3: Chindamo | C3: {=VLOOKUP(A3:B3,Dati!$A$2:$F$251,3,FALSE)} -> 22 | D3: #N/A | E3: {=VLOOKUP(A3:B3,Dati!$A$2:$F$251,4,FALSE)} -> Dottorato di ricerca | F3: #N/A | G3: {=VLOOKUP(A3:B3,Dati!A150:F399,6,FALSE)} -> Tecnico informatico | H3: #N/A
A4: Adriana | B4: Faranda | C4: {=VLOOKUP(A4:B4,Dati!$A$2:$F$251,3,FALSE)} -> 22 | D4: #N/A | E4: {=VLOOKUP(A4:B4,Dati!$A$2:$F$251,4,FALSE)} -> Dottorato di ricerca | F4: #N/A | G4: {=VLOOKUP(A4:B4,Dati!A188:F437,6,FALSE)} -> Analista dati | H4: #N/A
A5: Agnolo | B5: Ferrari | C5: {=VLOOKUP(A5:B5,Dati!$A$2:$F$251,3,FALSE)} -> 64 | D5: #N/A | E5: {=VLOOKUP(A5:B5,Dati!$A$2:$F$251,4,FALSE)} -> Diploma di scuola superiore | F5: #N/A | G5: {=VLOOKUP(A5:B5,Dati!A178:F427,6,FALSE)} -> Analista dati | H5: #N/A
A6: Agostino | B6: Polesel | C6: {=VLOOKUP(A6:B6,Dati!$A$2:$F$251,3,FALSE)} -> 32 | D6: #N/A | E6: {=VLOOKUP(A6:B6,Dati!$A$2:$F$251,4,FALSE)} -> Master | F6: #N/A | G6: {=VLOOKUP(A6:B6,Dati!A203:F452,6,FALSE)} -> Analista dati | H6: #N/A
A7: Alfredo | B7: Gabrieli | C7: {=VLOOKUP(A7:B7,Dati!$A$2:$F$251,3,FALSE)} -> 50 | D7: #N/A | E7: {=VLOOKUP(A7:B7,Dati!$A$2:$F$251,4,FALSE)} -> Laurea magistrale | F7: #N/A | G7: {=VLOOKUP(A7:B7,Dati!A19:F268,6,FALSE)} -> Tecnico informatico | H7: #N/A
A8: Alfredo | B8: Vigliotti | C8: {=VLOOKUP(A8:B8,Dati!$A$2:$F$251,3,FALSE)} -> 50 | D8: #N/A | E8: {=VLOOKUP(A8:B8,Dati!$A$2:$F$251,4,FALSE)} -> Laurea magistrale | F8: #N/A | G8: {=VLOOKUP(A8:B8,Dati!A182:F431,6,FALSE)} -> Project Manager | H8: #N/A
A9: Alina | B9: Jovinelli | C9: {=VLOOKUP(A9:B9,Dati!$A$2:$F$251,3,FALSE)} -> 22 | D9: #N/A | E9: {=VLOOKUP(A9:B9,Dati!$A$2:$F$251,4,FALSE)} -> Master | F9: #N/A | G9: {=VLOOKUP(A9:B9,Dati!A207:F456,6,FALSE)} -> Analista dati | H9: #N/A
A10: Allegra | B10: Guidone | C10: {=VLOOKUP(A10:B10,Dati!$A$2:$F$251,3,FALSE)} -> 63 | D10: #N/A | E10: {=VLOOKUP(A10:B10,Dati!$A$2:$F$251,4,FALSE)} -> Diploma di scuola superiore | F10: #N/A | G10: {=VLOOKUP(A10:B10,Dati!A22:F271,6,FALSE)} -> Analista dati | H10: #N/A
A11: Allegra | B11: Gagliano | C11: {=VLOOKUP(A11:B11,Dati!$A$2:$F$251,3,FALSE)} -> 63 | D11: #N/A | E11: {=VLOOKUP(A11:B11,Dati!$A$2:$F$251,4,FALSE)} -> Diploma di scuola superiore | F11: #N/A | G11: {=VLOOKUP(A11:B11,Dati!A220:F469,6,FALSE)} -> Impiegato amministrativo | H11: #N/A
A12: Allegra | B12: Baggio | C12: {=VLOOKUP(A12:B12,Dati!$A$2:$F$251,3,FALSE)} -> 63 | D12: #N/A | E12: {=VLOOKUP(A12:B12,Dati!$A$2:$F$251,4,FALSE)} -> Diploma di scuola superiore | F12: #N/A | G12: {=VLOOKUP(A12:B12,Dati!A231:F480,6,FALSE)} -> Responsabile vendite | H12: #N/A
A13: Amadeo | B13: Pastine | C13: {=VLOOKUP(A13:B13,Dati!$A$2:$F$251,3,FALSE)} -> 48 | D13: #N/A | E13: {=VLOOKUP(A13:B13,Dati!$A$2:$F$251,4,FALSE)} -> Laurea magistrale | F13: #N/A | G13: {=VLOOKUP(A13:B13,Dati!A86:F335,6,FALSE)} -> Direttore risorse umane | H13: #N/A
A14: Amico | B14: Saffi | C14: {=VLOOKUP(A14:B14,Dati!$A$2:$F$251,3,FALSE)} -> 27 | D14: #N/A | E14: {=VLOOKUP(A14:B14,Dati!$A$2:$F$251,4,FALSE)} -> Dottorato di ricerca | F14: #N/A | G14: {=VLOOKUP(A14:B14,Dati!A110:F359,6,FALSE)} -> Project Manager | H14: #N/A
A15: Angelica | B15: Moneta | C15: {=VLOOKUP(A15:B15,Dati!$A$2:$F$251,3,FALSE)} -> 21 | D15: #N/A | E15: {=VLOOKUP(A15:B15,Dati!$A$2:$F$251,4,FALSE)} -> Diploma di scuola superiore | F15: #N/A | G15: {=VLOOKUP(A15:B15,Dati!A243:F492,6,FALSE)} -> Tecnico informatico | H15: #N/A
A16: Angelo | B16: Pavone | C16: {=VLOOKUP(A16:B16,Dati!$A$2:$F$251,3,FALSE)} -> 65 | D16: #N/A | E16: {=VLOOKUP(A16:B16,Dati!$A$2:$F$251,4,FALSE)} -> Laurea magistrale | F16: #N/A | G16: {=VLOOKUP(A16:B16,Dati!A206:F455,6,FALSE)} -> Responsabile vendite | H16: #N/A
A17: Annalisa | B17: Pietrangeli | C17: {=VLOOKUP(A17:B17,Dati!$A$2:$F$251,3,FALSE)} -> 20 | D17: #N/A | E17: {=VLOOKUP(A17:B17,Dati!$A$2:$F$251,4,FALSE)} -> Laurea triennale | F17: #N/A | G17: {=VLOOKUP(A17:B17,Dati!A204:F453,6,FALSE)} -> Project Manager | H17: #N/A
A18: Annamaria | B18: Burcardo | C18: {=VLOOKUP(A18:B18,Dati!$A$2:$F$251,3,FALSE)} -> 40 | D18: #N/A | E18: {=VLOOKUP(A18:B18,Dati!$A$2:$F$251,4,FALSE)} -> Diploma di scuola superiore | F18: #N/A | G18: {=VLOOKUP(A18:B18,Dati!A27:F276,6,FALSE)} -> Tecnico informatico | H18: #N/A
A19: Annamaria | B19: Rocca | C19: {=VLOOKUP(A19:B19,Dati!$A$2:$F$251,3,FALSE)} -> 40 | D19: #N/A | E19: {=VLOOKUP(A19:B19,Dati!$A$2:$F$251,4,FALSE)} -> Diploma di scuola superiore | F19: #N/A | G19: {=VLOOKUP(A19:B19,Dati!A77:F326,6,FALSE)} -> Tecnico informatico | H19: #N/A
A20: Annetta | B20: Einaudi | C20: {=VLOOKUP(A20:B20,Dati!$A$2:$F$251,3,FALSE)} -> 46 | D20: #N/A | E20: {=VLOOKUP(A20:B20,Dati!$A$2:$F$251,4,FALSE)} -> Laurea magistrale | F20: #N/A | G20: {=VLOOKUP(A20:B20,Dati!A12:F261,6,FALSE)} -> Tecnico informatico | H20: #N/A
A21: Annibale | B21: Rossi | C21: {=VLOOKUP(A21:B21,Dati!$A$2:$F$251,3,FALSE)} -> 64 | D21: #N/A | E21: {=VLOOKUP(A21:B21,Dati!$A$2:$F$251,4,FALSE)} -> Laurea magistrale | F21: #N/A | G21: {=VLOOKUP(A21:B21,Dati!A50:F299,6,FALSE)} -> Impiegato amministrativo | H21: #N/A
A22: Antonello | B22: Giammusso | C22: {=VLOOKUP(A22:B22,Dati!$A$2:$F$251,3,FALSE)} -> 36 | D22: #N/A | E22: {=VLOOKUP(A22:B22,Dati!$A$2:$F$251,4,FALSE)} -> Laurea triennale | F22: #N/A | G22: {=VLOOKUP(A22:B22,Dati!A15:F264,6,FALSE)} -> Responsabile vendite | H22: #N/A
A23: Antonino | B23: Casagrande | C23: {=VLOOKUP(A23:B23,Dati!$A$2:$F$251,3,FALSE)} -> 56 | D23: #N/A | E23: {=VLOOKUP(A23:B23,Dati!$A$2:$F$251,4,FALSE)} -> Diploma di scuola superiore | F23: #N/A | G23: {=VLOOKUP(A23:B23,Dati!A94:F343,6,FALSE)} -> Responsabile vendite | H23: #N/A
A24: Arturo | B24: Malaparte | C24: {=VLOOKUP(A24:B24,Dati!$A$2:$F$251,3,FALSE)} -> 32 | D24: #N/A | E24: {=VLOOKUP(A24:B24,Dati!$A$2:$F$251,4,FALSE)} -> Dottorato di ricerca | F24: #N/A | G24: {=VLOOKUP(A24:B24,Dati!A70:F319,6,FALSE)} -> Responsabile vendite | H24: #N/A
A25: Atenulf | B25: Pizzo | C25: {=VLOOKUP(A25:B25,Dati!$A$2:$F$251,3,FALSE)} -> 24 | D25: #N/A | E25: {=VLOOKUP(A25:B25,Dati!$A$2:$F$251,4,FALSE)} -> Diploma di scuola superiore | F25: #N/A | G25: {=VLOOKUP(A25:B25,Dati!A105:F354,6,FALSE)} -> Marketing Specialist | H25: #N/A
A26: Azeglio | B26: Lombardi | C26: {=VLOOKUP(A26:B26,Dati!$A$2:$F$251,3,FALSE)} -> 51 | D26: #N/A | E26: {=VLOOKUP(A26:B26,Dati!$A$2:$F$251,4,FALSE)} -> Laurea triennale | F26: #N/A | G26: {=VLOOKUP(A26:B26,Dati!A126:F375,6,FALSE)} -> Operaio specializzato | H26: #N/A
A27: Baccio | B27: Gabbana | C27: {=VLOOKUP(A27:B27,Dati!$A$2:$F$251,3,FALSE)} -> 21 | D27: #N/A | E27: {=VLOOKUP(A27:B27,Dati!$A$2:$F$251,4,FALSE)} -> Laurea triennale | F27: #N/A | G27: {=VLOOKUP(A27:B27,Dati!A7:F256,6,FALSE)} -> Responsabile vendite | H27: #N/A
A28: Beatrice | B28: Lerner | C28: {=VLOOKUP(A28:B28,Dati!$A$2:$F$251,3,FALSE)} -> 52 | D28: #N/A | E28: {=VLOOKUP(A28:B28,Dati!$A$2:$F$251,4,FALSE)} -> Master | F28: #N/A | G28: {=VLOOKUP(A28:B28,Dati!A4:F253,6,FALSE)} -> Operaio specializzato | H28: #N/A
A29: Beatrice | B29: Salvo | C29: {=VLOOKUP(A29:B29,Dati!$A$2:$F$251,3,FALSE)} -> 52 | D29: #N/A | E29: {=VLOOKUP(A29:B29,Dati!$A$2:$F$251,4,FALSE)} -> Master | F29: #N/A | G29: {=VLOOKUP(A29:B29,Dati!A73:F322,6,FALSE)} -> Marketing Specialist | H29: #N/A
A30: Beatrice | B30: Bresciani | C30: {=VLOOKUP(A30:B30,Dati!$A$2:$F$251,3,FALSE)} -> 52 | D30: #N/A | E30: {=VLOOKUP(A30:B30,Dati!$A$2:$F$251,4,FALSE)} -> Master | F30: #N/A | G30: {=VLOOKUP(A30:B30,Dati!A165:F414,6,FALSE)} -> Tecnico informatico | H30: #N/A
A31: Berenice | B31: Cianciolo | C31: {=VLOOKUP(A31:B31,Dati!$A$2:$F$251,3,FALSE)} -> 49 | D31: #N/A | E31: {=VLOOKUP(A31:B31,Dati!$A$2:$F$251,4,FALSE)} -> Laurea triennale | F31: #N/A | G31: {=VLOOKUP(A31:B31,Dati!A125:F374,6,FALSE)} -> Tecnico informatico | H31: #N/A
A32: Bernardo | B32: Nitto | C32: {=VLOOKUP(A32:B32,Dati!$A$2:$F$251,3,FALSE)} -> 56 | D32: #N/A | E32: {=VLOOKUP(A32:B32,Dati!$A$2:$F$251,4,FALSE)} -> Master | F32: #N/A | G32: {=VLOOKUP(A32:B32,Dati!A102:F351,6,FALSE)} -> Operaio specializzato | H32: #N/A
A33: Biagio | B33: Canetta | C33: {=VLOOKUP(A33:B33,Dati!$A$2:$F$251,3,FALSE)} -> 49 | D33: #N/A | E33: {=VLOOKUP(A33:B33,Dati!$A$2:$F$251,4,FALSE)} -> Master | F33: #N/A | G33: {=VLOOKUP(A33:B33,Dati!A164:F413,6,FALSE)} -> Marketing Specialist | H33: #N/A
A34: Bianca | B34: Salieri | C34: {=VLOOKUP(A34:B34,Dati!$A$2:$F$251,3,FALSE)} -> 59 | D34: #N/A | E34: {=VLOOKUP(A34:B34,Dati!$A$2:$F$251,4,FALSE)} -> Laurea triennale | F34: #N/A | G34: {=VLOOKUP(A34:B34,Dati!A123:F372,6,FALSE)} -> Direttore risorse umane | H34: #N/A
A35: Bianca | B35: Pulci | C35: {=VLOOKUP(A35:B35,Dati!$A$2:$F$251,3,FALSE)} -> 59 | D35: #N/A | E35: {=VLOOKUP(A35:B35,Dati!$A$2:$F$251,4,FALSE)} -> Laurea triennale | F35: #N/A | G35: {=VLOOKUP(A35:B35,Dati!A172:F421,6,FALSE)} -> Responsabile vendite | H35: #N/A
A36: Bruno | B36: Mogherini | C36: {=VLOOKUP(A36:B36,Dati!$A$2:$F$251,3,FALSE)} -> 48 | D36: #N/A | E36: {=VLOOKUP(A36:B36,Dati!$A$2:$F$251,4,FALSE)} -> Dottorato di ricerca | F36: #N/A | G36: {=VLOOKUP(A36:B36,Dati!A237:F486,6,FALSE)} -> Direttore risorse umane | H36: #N/A
A37: Calogero | B37: Monduzzi | C37: {=VLOOKUP(A37:B37,Dati!$A$2:$F$251,3,FALSE)} -> 49 | D37: #N/A | E37: {=VLOOKUP(A37:B37,Dati!$A$2:$F$251,4,FALSE)} -> Laurea triennale | F37: #N/A | G37: {=VLOOKUP(A37:B37,Dati!A48:F297,6,FALSE)} -> Tecnico informatico | H37: #N/A
A38: Camilla | B38: Zaccardo | C38: {=VLOOKUP(A38:B38,Dati!$A$2:$F$251,3,FALSE)} -> 20 | D38: #N/A | E38: {=VLOOKUP(A38:B38,Dati!$A$2:$F$251,4,FALSE)} -> Diploma di scuola superiore | F38: #N/A | G38: {=VLOOKUP(A38:B38,Dati!A62:F311,6,FALSE)} -> Contabile | H38: #N/A
A39: Carla | B39: Travaglio | C39: {=VLOOKUP(A39:B39,Dati!$A$2:$F$251,3,FALSE)} -> 61 | D39: #N/A | E39: {=VLOOKUP(A39:B39,Dati!$A$2:$F$251,4,FALSE)} -> Diploma di scuola superiore | F39: #N/A | G39: {=VLOOKUP(A39:B39,Dati!A112:F361,6,FALSE)} -> Marketing Specialist | H39: #N/A
A40: Carolina | B40: Impastato | C40: {=VLOOKUP(A40:B40,Dati!$A$2:$F$251,3,FALSE)} -> 49 | D40: #N/A | E40: {=VLOOKUP(A40:B40,Dati!$A$2:$F$251,4,FALSE)} -> Laurea magistrale | F40: #N/A | G40: {=VLOOKUP(A40:B40,Dati!A72:F321,6,FALSE)} -> Direttore risorse umane | H40: #N/A
...

Sheet Pivot e analisi
A3: Titolo di studio | B3: Numero dipendenti | E3: Porfessione | F3: Numero dipendenti | H3: Titolo di studio | I3: Numero dipendenti | K3: Titolo di studio | L3: Numero dipendenti
A4: Diploma di scuola superiore | B4: 78 | E4: Addetto logistica | F4: 22 | H4: Diploma di scuola superiore | K4: Laurea magistrale
A5: Dottorato di ricerca | B5: 44 | E5: Analista dati | F5: 21 | H5: Addetto logistica | I5: 4 | K5: Addetto logistica | L5: 2
A6: Laurea magistrale | B6: 37 | E6: Contabile | F6: 18 | H6: Analista dati | I6: 8 | K6: Analista dati | L6: 2
A7: Laurea triennale | B7: 39 | E7: Direttore risorse umane | F7: 24 | H7: Contabile | I7: 6 | K7: Contabile | L7: 4
A8: Master | B8: 52 | E8: Impiegato amministrativo | F8: 23 | H8: Direttore risorse umane | I8: 6 | K8: Direttore risorse umane | L8: 6
A9: Totale complessivo | B9: 250 | E9: Marketing Specialist | F9: 27 | H9: Impiegato amministrativo | I9: 8 | K9: Impiegato amministrativo | L9: 4
E10: Operaio specializzato | F10: 29 | H10: Marketing Specialist | I10: 7 | K10: Marketing Specialist | L10: 3
E11: Project Manager | F11: 28 | H11: Operaio specializzato | I11: 12 | K11: Operaio specializzato | L11: 4
A12: Età | B12: Numero dipendenti | E12: Responsabile vendite | F12: 33 | H12: Project Manager | I12: 12 | K12: Project Manager | L12: 1
A13: 20 | B13: 6 | E13: Tecnico informatico | F13: 25 | H13: Responsabile vendite | I13: 8 | K13: Responsabile vendite | L13: 4
A14: 21 | B14: 5 | E14: Totale complessivo | F14: 250 | H14: Tecnico informatico | I14: 7 | K14: Tecnico informatico | L14: 7
A15: 22 | B15: 7 | H15: Totale | I15: =SUM(I5:I14) -> 78 | K15: Totale | L15: =SUM(L5:L14) -> 37
A16: 23 | B16: 2 | E16: Titolo di studio | F16: Numero dipendenti
A17: 24 | B17: 4 | E17: Diploma di scuola superiore | F17: 78 | H17: Titolo di studio | I17: Numero dipendenti | K17: Titolo di studio | L17: Numero dipendenti
A18: 25 | B18: 6 | E18: Dottorato di ricerca | F18: 44 | H18: Dottorato di ricerca | K18: Laurea triennale
A19: 26 | B19: 4 | E19: Laurea magistrale | F19: 37 | H19: Addetto logistica | I19: 5 | K19: Addetto logistica | L19: 3
A20: 27 | B20: 6 | E20: Laurea triennale | F20: 39 | H20: Analista dati | I20: 5 | K20: Analista dati | L20: 1
A21: 28 | B21: 2 | E21: Master | F21: 52 | H21: Contabile | I21: 2 | K21: Contabile | L21: 1
A22: 29 | B22: 10 | E22: Totale complessivo | F22: 250 | H22: Direttore risorse umane | I22: 4 | K22: Direttore risorse umane | L22: 4
A23: 30 | B23: 8 | H23: Impiegato amministrativo | I23: 5 | K23: Impiegato amministrativo | L23: 3
A24: 31 | B24: 4 | H24: Marketing Specialist | I24: 6 | K24: Marketing Specialist | L24: 3
A25: 32 | B25: 12 | E25: Fascia d'età | F25: Totale | H25: Operaio specializzato | I25: 1 | K25: Operaio specializzato | L25: 6
A26: 33 | B26: 7 | E26: 18-35 | F26: =COUNTIF('Dati sistemati'!$C$2:$C$251,">35") -> 155 | H26: Project Manager | I26: 6 | K26: Project Manager | L26: 3
A27: 34 | B27: 3 | E27: 35-60 | F27: =250-(F26+F28) -> 64 | H27: Responsabile vendite | I27: 7 | K27: Responsabile vendite | L27: 10
A28: 35 | B28: 9 | E28: Over 60 | F28: =COUNTIF('Dati sistemati'!$C$2:$C$251,">60") -> 31 | H28: Tecnico informatico | I28: 3 | K28: Tecnico informatico | L28: 5
A29: 36 | B29: 6 | E29: Totale complessivo | F29: =SUM(F26:F28) -> 250 | H29: Totale | I29: =SUM(I19:I28) -> 44 | K29: Totale | L29: =SUM(L19:L28) -> 39
A30: 37 | B30: 5
A31: 38 | B31: 3 | H31: Titolo di studio | I31: Numero dipendenti
A32: 39 | B32: 3 | H32: Master
A33: 40 | B33: 5 | H33: Addetto logistica | I33: 8
A34: 41 | B34: 3 | H34: Analista dati | I34: 5
A35: 42 | B35: 12 | H35: Contabile | I35: 5
A36: 43 | B36: 6 | H36: Direttore risorse umane | I36: 4
A37: 44 | B37: 2 | H37: Impiegato amministrativo | I37: 3
A38: 45 | B38: 6 | H38: Marketing Specialist | I38: 8
A39: 46 | B39: 5 | H39: Operaio specializzato | I39: 6
A40: 47 | B40: 4 | H40: Project Manager | I40: 6
A41: 48 | B41: 3 | H41: Responsabile vendite | I41: 4
A42: 49 | B42: 7 | H42: Tecnico informatico | I42: 3
...

Sheet Grafici
A1: Organigramma | N1: Diploma di scuola superiore | AI1: Laurea Magistrale | BD1: Dottorato di ricerca
N30: Laurea Triennale | AI30: Master
CA100: ?
